2023-04-11 18:20:58,788 - minecraft.networking.connection - INFO - Connecting to simplesmp.net:25565 with protocol version 762 (1.19.4)
2023-04-11 18:20:58,951 - minecraft.networking.connection - INFO - Started read/write tasks
2023-04-11 18:20:58,951 - minecraft.networking.connection - INFO - Beginning standard login flow
2023-04-11 18:20:58,952 - minecraft.networking.connection - INFO - Connection state changed to LOGIN
2023-04-11 18:20:59,109 - minecraft.networking.connection - INFO - Dispatching EncryptionRequest to reactor handler
2023-04-11 18:20:59,912 - minecraft.networking.connection - INFO - Dispatching SetCompression to reactor handler
2023-04-11 18:20:59,912 - minecraft.networking.reactors.login - INFO - Server requested compression with threshold 64
2023-04-11 18:20:59,913 - minecraft.networking.connection - INFO - Dispatching LoginSuccess to reactor handler
2023-04-11 18:20:59,913 - minecraft.networking.reactors.login - INFO - Successful login as plun1331
2023-04-11 18:20:59,914 - minecraft.networking.connection - INFO - Connection state changed to PLAY
2023-04-11 18:20:59,931 - minecraft.networking.connection - INFO - Dispatching LoginPlay to reactor handler
2023-04-11 18:20:59,935 - minecraft.networking.connection - INFO - Dispatching Ping to reactor handler
2023-04-11 18:21:00,396 - minecraft.networking.connection - INFO - Dispatching Ping to reactor handler
2023-04-11 18:21:00,397 - minecraft.networking.connection - INFO - Dispatching SynchronizePlayerPosition to reactor handler
2023-04-11 18:21:00,398 - minecraft.networking.connection - INFO - Dispatching Ping to reactor handler
2023-04-11 18:21:00,458 - minecraft.networking.connection - INFO - Dispatching Ping to reactor handler
2023-04-11 18:21:00,477 - minecraft.networking.connection - INFO - Dispatching Ping to reactor handler
2023-04-11 18:21:00,482 - minecraft.networking.connection - ERROR - Reader < Failed to parse packet with id 39
Traceback (most recent call last):
  File "/workspaces/MCPy/minecraft/packets/__init__.py", line 87, in get_packet
    return packet.from_bytes(data)
           ^^^^^^^^^^^^^^^^^^^^^^^
  File "/workspaces/MCPy/minecraft/packets/play_clientbound.py", line 2087, in from_bytes
    arr_length = Varint.from_bytes(data).value
                 ^^^^^^^^^^^^^^^^^^^^^^^
  File "/workspaces/MCPy/minecraft/datatypes.py", line 402, in from_bytes
    raise ValueError("Varint is too big")
ValueError: Varint is too big

The above exception was the direct cause of the following exception:

Traceback (most recent call last):
  File "/workspaces/MCPy/minecraft/networking/connection.py", line 298, in _read_loop
    packet = get_packet(packet_data, state=self.state)
             ^^^^^^^^^^^^^^^^^^^^^^^^^^^^^^^^^^^^^^^^^
  File "/workspaces/MCPy/minecraft/packets/__init__.py", line 89, in get_packet
    raise PacketParsingError(e, packet_id, original_data) from e
minecraft.exceptions.PacketParsingError: Failed to parse packet with ID 39: Varint is too big
2023-04-11 18:21:00,485 - minecraft.networking.connection - INFO - Dispatching Ping to reactor handler
2023-04-11 18:21:00,486 - minecraft.networking.connection - ERROR - Reader < Failed to parse packet with id 39
Traceback (most recent call last):
  File "/workspaces/MCPy/minecraft/packets/__init__.py", line 87, in get_packet
    return packet.from_bytes(data)
           ^^^^^^^^^^^^^^^^^^^^^^^
  File "/workspaces/MCPy/minecraft/packets/play_clientbound.py", line 2087, in from_bytes
    arr_length = Varint.from_bytes(data).value
                 ^^^^^^^^^^^^^^^^^^^^^^^
  File "/workspaces/MCPy/minecraft/datatypes.py", line 402, in from_bytes
    raise ValueError("Varint is too big")
ValueError: Varint is too big

The above exception was the direct cause of the following exception:

Traceback (most recent call last):
  File "/workspaces/MCPy/minecraft/networking/connection.py", line 298, in _read_loop
    packet = get_packet(packet_data, state=self.state)
             ^^^^^^^^^^^^^^^^^^^^^^^^^^^^^^^^^^^^^^^^^
  File "/workspaces/MCPy/minecraft/packets/__init__.py", line 89, in get_packet
    raise PacketParsingError(e, packet_id, original_data) from e
minecraft.exceptions.PacketParsingError: Failed to parse packet with ID 39: Varint is too big
2023-04-11 18:21:00,487 - minecraft.networking.connection - ERROR - Reader < Failed to parse packet with id 39
Traceback (most recent call last):
  File "/workspaces/MCPy/minecraft/packets/__init__.py", line 87, in get_packet
    return packet.from_bytes(data)
           ^^^^^^^^^^^^^^^^^^^^^^^
  File "/workspaces/MCPy/minecraft/packets/play_clientbound.py", line 2087, in from_bytes
    arr_length = Varint.from_bytes(data).value
                 ^^^^^^^^^^^^^^^^^^^^^^^
  File "/workspaces/MCPy/minecraft/datatypes.py", line 402, in from_bytes
    raise ValueError("Varint is too big")
ValueError: Varint is too big

The above exception was the direct cause of the following exception:

Traceback (most recent call last):
  File "/workspaces/MCPy/minecraft/networking/connection.py", line 298, in _read_loop
    packet = get_packet(packet_data, state=self.state)
             ^^^^^^^^^^^^^^^^^^^^^^^^^^^^^^^^^^^^^^^^^
  File "/workspaces/MCPy/minecraft/packets/__init__.py", line 89, in get_packet
    raise PacketParsingError(e, packet_id, original_data) from e
minecraft.exceptions.PacketParsingError: Failed to parse packet with ID 39: Varint is too big
2023-04-11 18:21:00,489 - minecraft.networking.connection - ERROR - Reader < Failed to parse packet with id 39
Traceback (most recent call last):
  File "/workspaces/MCPy/minecraft/packets/__init__.py", line 87, in get_packet
    return packet.from_bytes(data)
           ^^^^^^^^^^^^^^^^^^^^^^^
  File "/workspaces/MCPy/minecraft/packets/play_clientbound.py", line 2087, in from_bytes
    arr_length = Varint.from_bytes(data).value
                 ^^^^^^^^^^^^^^^^^^^^^^^
  File "/workspaces/MCPy/minecraft/datatypes.py", line 402, in from_bytes
    raise ValueError("Varint is too big")
ValueError: Varint is too big

The above exception was the direct cause of the following exception:

Traceback (most recent call last):
  File "/workspaces/MCPy/minecraft/networking/connection.py", line 298, in _read_loop
    packet = get_packet(packet_data, state=self.state)
             ^^^^^^^^^^^^^^^^^^^^^^^^^^^^^^^^^^^^^^^^^
  File "/workspaces/MCPy/minecraft/packets/__init__.py", line 89, in get_packet
    raise PacketParsingError(e, packet_id, original_data) from e
minecraft.exceptions.PacketParsingError: Failed to parse packet with ID 39: Varint is too big
2023-04-11 18:21:00,490 - minecraft.networking.connection - ERROR - Reader < Failed to parse packet with id 39
Traceback (most recent call last):
  File "/workspaces/MCPy/minecraft/packets/__init__.py", line 87, in get_packet
    return packet.from_bytes(data)
           ^^^^^^^^^^^^^^^^^^^^^^^
  File "/workspaces/MCPy/minecraft/packets/play_clientbound.py", line 2087, in from_bytes
    arr_length = Varint.from_bytes(data).value
                 ^^^^^^^^^^^^^^^^^^^^^^^
  File "/workspaces/MCPy/minecraft/datatypes.py", line 402, in from_bytes
    raise ValueError("Varint is too big")
ValueError: Varint is too big

The above exception was the direct cause of the following exception:

Traceback (most recent call last):
  File "/workspaces/MCPy/minecraft/networking/connection.py", line 298, in _read_loop
    packet = get_packet(packet_data, state=self.state)
             ^^^^^^^^^^^^^^^^^^^^^^^^^^^^^^^^^^^^^^^^^
  File "/workspaces/MCPy/minecraft/packets/__init__.py", line 89, in get_packet
    raise PacketParsingError(e, packet_id, original_data) from e
minecraft.exceptions.PacketParsingError: Failed to parse packet with ID 39: Varint is too big
2023-04-11 18:21:00,493 - minecraft.networking.connection - INFO - Dispatching Ping to reactor handler
2023-04-11 18:21:00,494 - minecraft.networking.connection - INFO - Dispatching Ping to reactor handler
2023-04-11 18:21:00,495 - minecraft.networking.connection - ERROR - Reader < Failed to parse packet with id 105
Traceback (most recent call last):
  File "/workspaces/MCPy/minecraft/packets/__init__.py", line 87, in get_packet
    return packet.from_bytes(data)
           ^^^^^^^^^^^^^^^^^^^^^^^
  File "/workspaces/MCPy/minecraft/packets/play_clientbound.py", line 5540, in from_bytes
    value = Advancement.from_bytes(data)
            ^^^^^^^^^^^^^^^^^^^^^^^^^^^^
  File "/workspaces/MCPy/minecraft/datatypes.py", line 1653, in from_bytes
    display_data = DataProxy.from_bytes(data)
                   ^^^^^^^^^^^^^^^^^^^^
AttributeError: type object 'DataProxy' has no attribute 'from_bytes'

The above exception was the direct cause of the following exception:

Traceback (most recent call last):
  File "/workspaces/MCPy/minecraft/networking/connection.py", line 298, in _read_loop
    packet = get_packet(packet_data, state=self.state)
             ^^^^^^^^^^^^^^^^^^^^^^^^^^^^^^^^^^^^^^^^^
  File "/workspaces/MCPy/minecraft/packets/__init__.py", line 89, in get_packet
    raise PacketParsingError(e, packet_id, original_data) from e
minecraft.exceptions.PacketParsingError: Failed to parse packet with ID 105: type object 'DataProxy' has no attribute 'from_bytes'
2023-04-11 18:21:00,543 - minecraft.networking.connection - ERROR - Reader : Error in read loop
Traceback (most recent call last):
  File "/workspaces/MCPy/minecraft/networking/connection.py", line 246, in _read_loop
    packet_data = self.decrypt(await self.reader.readexactly(packet_length))
                               ^^^^^^^^^^^^^^^^^^^^^^^^^^^^^^^^^^^^^^^^^^^^
  File "/usr/local/lib/python3.11/asyncio/streams.py", line 728, in readexactly
    await self._wait_for_data('readexactly')
  File "/usr/local/lib/python3.11/asyncio/streams.py", line 522, in _wait_for_data
    await self._waiter
  File "/usr/local/lib/python3.11/asyncio/selector_events.py", line 995, in _read_ready__data_received
    data = self._sock.recv(self.max_size)
           ^^^^^^^^^^^^^^^^^^^^^^^^^^^^^^
ConnectionResetError: [Errno 104] Connection reset by peer
2023-04-11 18:21:00,544 - minecraft.networking.connection - INFO - Closing connection
2023-04-11 18:21:00,544 - minecraft.networking.connection - ERROR - Writer : Write loop cancelled
